output-example/example.json
[
    {
        "price": 33990,
        "symbol": "BTC-USDT",
        "amount": 177.60000000000016,
        "total": 6036624.000000006,
        "side": "BUY_1",
        "cum_sum": 6036624.000000006
    },
    {
        "price": 33985,
        "symbol": "BTC-USDT",
        "amount": 195.02999999999986,
        "total": 6628094.549999995,
        "side": "BUY_2",
        "cum_sum": 12664718.55
    },
    {
        "price": 33980,
        "symbol": "BTC-USDT",
        "amount": 197.87000000000003,
        "total": 6723622.6000000015,
        "side": "BUY_3",
        "cum_sum": 19388341.150000002
    },
    {
        "price": 33975,
        "symbol": "BTC-USDT",
        "amount": 160.93,
        "total": 5467596.75,
        "side": "BUY_4",
        "cum_sum": 24855937.900000002
    },
    {
        "price": 33970,
        "symbol": "BTC-USDT",
        "amount": 170.19000000000003,
        "total": 5781354.300000001,
        "side": "BUY_5",
        "cum_sum": 30637292.200000003
    },
    {
        "price": 33965,
        "symbol": "BTC-USDT",
        "amount": 183.73999999999995,
        "total": 6240729.099999999,
        "side": "BUY_6",
        "cum_sum": 36878021.300000004
    },
    {
        "price": 33960,
        "symbol": "BTC-USDT",
        "amount": 190.54999999999995,
        "total": 6471077.999999998,
        "side": "BUY_7",
        "cum_sum": 43349099.300000004
    },
    {
        "price": 33955,
        "symbol": "BTC-USDT",
        "amount": 178.40000000000003,
        "total": 6057572.000000001,
        "side": "BUY_8",
        "cum_sum": 49406671.300000004
    },
    {
        "price": 33950,
        "symbol": "BTC-USDT",
        "amount": 186.13000000000014,
        "total": 6319113.500000005,
        "side": "BUY_9",
        "cum_sum": 55725784.80000001
    },
    {
        "price": 34010,
        "symbol": "BTC-USDT",
        "amount": 193.38,
        "total": 6576853.8,
        "side": "SELL_1",
        "cum_sum": 6576853.8
    },
    {
        "price": 34015,
        "symbol": "BTC-USDT",
        "amount": 178.35999999999996,
        "total": 6066915.3999999985,
        "side": "SELL_2",
        "cum_sum": 12643769.2
    },
    {
        "price": 34020,
        "symbol": "BTC-USDT",
        "amount": 186.32000000000008,
        "total": 6338606.400000002,
        "side": "SELL_3",
        "cum_sum": 18982375.6
    },
    {
        "price": 34025,
        "symbol": "BTC-USDT",
        "amount": 184.56999999999994,
        "total": 6279994.249999998,
        "side": "SELL_4",
        "cum_sum": 25262369.85
    },
    {
        "price": 34030,
        "symbol": "BTC-USDT",
        "amount": 183.98999999999987,
        "total": 6261179.6999999955,
        "side": "SELL_5",
        "cum_sum": 31523549.549999997
    },
    {
        "price": 34035,
        "symbol": "BTC-USDT",
        "amount": 188.33999999999997,
        "total": 6410151.899999999,
        "side": "SELL_6",
        "cum_sum": 37933701.449999996
    },
    {
        "price": 34040,
        "symbol": "BTC-USDT",
        "amount": 181.33999999999992,
        "total": 6172813.599999997,
        "side": "SELL_7",
        "cum_sum": 44106515.04999999
    },
    {
        "price": 34045,
        "symbol": "BTC-USDT",
        "amount": 182.4599999999999,
        "total": 6211850.699999996,
        "side": "SELL_8",
        "cum_sum": 50318365.749999985
    },
    {
        "price": 34050,
        "symbol": "BTC-USDT",
        "amount": 179.61999999999998,
        "total": 6116060.999999999,
        "side": "SELL_9",
        "cum_sum": 56434426.749999985
    }
]
